Workbook

Sheet Information

Sheet Depreciation Calculator
C2: Coachx.live
C3: Depreciation Calculator
B5: Straight Line Method
B6: Asset Cost | D6: 450000
B7: Additonal Asset Cost | D7: 50000
B8: Asset Price | D8: =D6+D7 -> 500000
B9: Scrap Value | D9: 50000
B10: Estimated Life Span (Years) | D10: 10
B11: Depreciation / Year as per Straight Line Method | D11: =D8-D9/D10 -> 495000
B12: Depreciation Percentage | D12: =IFERROR(D11/D8,"") -> 0.99
B13: Total Depreciation For Its Life Span | D13: =D11*D10 -> 4950000
B14: Depreciated Book Value After Its Life Span | D14: =IF(D8="", "", D8-D13) -> -4450000
B15: Balance Amount | D15: =IF(D8="", "", D9-D14) -> 4500000
B17: Diminishing Balance Method
B18: Asset Cost | D18: 450000
B19: Additonal Asset Cost | D19: 50000
B20: Asset Price | D20: =D18+D19 -> 500000
B21: Scrap Value | D21: 50000
B22: Estimated Life Span (Years) | D22: 10
B23: Rate of Depreciation as per Diminishing Balance Method | D23: =IF(D20="","",1-(D21/D20)^(1/D22)) -> 0.20567177
B24: Depreciation Schedule
B25: Year | C25: Year on Year Depreciation Amount | D25: Book Value
B26: 1 | C26: =D26*D23 -> 102835.88 | D26: =D8 -> 500000
B27: 2 | C27: =D27*D23 -> 81685.445 | D27: =D26-C26 -> 397164.12
B28: 3 | C28: =IFERROR(IF(D28>$D$21, (D28*$D$23), ""),"") -> 64885.055 | D28: =IFERROR(D27-C27, "") -> 315478.67
B29: 4 | C29: =IFERROR(IF(D29>$D$21, (D29*$D$23), ""),"") -> 51540.032 | D29: =IFERROR(D28-C28, "") -> 250593.62
B30: 5 | C30: =IFERROR(IF(D30>$D$21, (D30*$D$23), ""),"") -> 40939.702 | D30: =IFERROR(D29-C29, "") -> 199053.59
B31: 6 | C31: =IFERROR(IF(D31>$D$21, (D31*$D$23), ""),"") -> 32519.561 | D31: =IFERROR(D30-C30, "") -> 158113.88
B32: 7 | C32: =IFERROR(IF(D32>$D$21, (D32*$D$23), ""),"") -> 25831.206 | D32: =IFERROR(D31-C31, "") -> 125594.32
B33: 8 | C33: =IFERROR(IF(D33>$D$21, (D33*$D$23), ""),"") -> 20518.456 | D33: =IFERROR(D32-C32, "") -> 99763.116
B34: 9 | C34: =IFERROR(IF(D34>$D$21, (D34*$D$23), ""),"") -> 16298.389 | D34: =IFERROR(D33-C33, "") -> 79244.66
B35: 10 | C35: =IFERROR(IF(D35>$D$21, (D35*$D$23), ""),"") -> 12946.271 | D35: =IFERROR(D34-C34, "") -> 62946.271
C36: =IFERROR(IF(D36>$D$21, (D36*$D$23), ""),"")
C37: =IFERROR(IF(D37>$D$21, (D37*$D$23), ""),"") | D37: =IFERROR(D36-C36, "")
C38: =IFERROR(IF(D38>$D$21, (D38*$D$23), ""),"") | D38: =IFERROR(D37-C37, "")
C39: =IFERROR(IF(D39>$D$21, (D39*$D$23), ""),"") | D39: =IFERROR(D38-C38, "")
C40: =IFERROR(IF(D40>$D$21, (D40*$D$23), ""),"") | D40: =IFERROR(D39-C39, "")
C41: =IFERROR(IF(D41>$D$21, (D41*$D$23), ""),"") | D41: =IFERROR(D40-C40, "")
C42: =IFERROR(IF(D42>$D$21, (D42*$D$23), ""),"") | D42: =IFERROR(D41-C41, "")
C43: =IFERROR(IF(D43>$D$21, (D43*$D$23), ""),"") | D43: =IFERROR(D42-C42, "")
...

Sheet Sheet1
B2: 1. Annual depreciation (SLM) | D2: 6 Book value in 4th year
B3: Formula:- | D3: Formula:-
B4: (Asset Price - Scrap Value) / Life Span | D4: Book Value Year3 - Depreciation Year3
B5: ='Depreciation Calculator'!D8-'Depreciation Calculator'!D9/'Depreciation Calculator'!D10 -> 495000 | D5: ='Depreciation Calculator'!D28-'Depreciation Calculator'!C28 -> 250593.62
B7: 2 Total depreciation | D7: 7 Total depreciation (DBM)
B8: Formula:- | D8: Formula:-
B9: Annual Depreciation * Life Span | D9: SUM(all yearly Depreciation)
B10: ='Depreciation Calculator'!D11*'Depreciation Calculator'!D10 -> 4950000 | D10: =SUM('Depreciation Calculator'!C26:C35) -> 450000
B12: 3 Book value after life span | D12: 8 Book value after life span
B13: Formula:- | D13: Formula:-
B14: Scrap Value | D14: Last Year Book Value
B15: ='Depreciation Calculator'!D9 -> 50000 | D15: ='Depreciation Calculator'!D35 -> 62946.271
B17: 4 Rate of depreciation (DBM) | D17: 9 Comparison
B18: Formula:- | D18: Straight Line Method → Same depreciation every year
B19: Depreciation per year / Asset Price | D19: Diminishing Balance Method → Higher depreciation in early years
B20: ='Depreciation Calculator'!C26/'Depreciation Calculator'!D20 -> 0.20567177
B22: 5 Depreciation in 2nd year
B23: Formula:-
B24: Book Value Year2 × Rate
B25: ='Depreciation Calculator'!D27*'Depreciation Calculator'!D23 -> 81685.445

Sheet Sheet2
A1: Row Labels | B1: Sum of Asset Value
A2: 1 | B2: 495000
A3: 2 | B3: 490000
A4: 3 | B4: 485000
A5: 4 | B5: 480000
A6: 5 | B6: 475000
A7: 6 | B7: 470000
A8: 7 | B8: 465000
A9: 8 | B9: 460000
A10: 9 | B10: 455000
A11: 10 | B11: 450000
A12: Grand Total | B12: 4725000

Sheet Sheet3
A3: Row Labels | B3: Sum of Book Value
A4: 1 | B4: 500000
A5: 2 | B5: 397164.12
A6: 3 | B6: 315478.67
A7: 4 | B7: 250593.62
A8: 5 | B8: 199053.59
A9: 6 | B9: 158113.88
A10: 7 | B10: 125594.32
A11: 8 | B11: 99763.116
A12: 9 | B12: 79244.66
A13: 10 | B13: 62946.271
A14: Grand Total | B14: 2187952.2

Sheet Sheet4
A3: Row Labels | B3: Book Value | C3: Asset Value
A4: 1 | B4: 500000 | C4: 495000
A5: 2 | B5: 397164.12 | C5: 490000
A6: 3 | B6: 315478.67 | C6: 485000
A7: 4 | B7: 250593.62 | C7: 480000
A8: 5 | B8: 199053.59 | C8: 475000
A9: 6 | B9: 158113.88 | C9: 470000
A10: 7 | B10: 125594.32 | C10: 465000
A11: 8 | B11: 99763.116 | C11: 460000
A12: 9 | B12: 79244.66 | C12: 455000
A13: 10 | B13: 62946.271 | C13: 450000
A14: Grand Total | B14: 2187952.2 | C14: 4725000
